Workbook

Sheet Master_Site
A1: id13 | B1: slug | C1: titre_norm | D1: sous_titre_norm | E1: credit_ligne | F1: auteurs | G1: direction | H1: traduction | I1: compilation | J1: editeur | K1: Marque | L1: collection | M1: Nombre séquentiel | N1: date_parution_norm | O1: Numéro d'édition | P1: format_site | Q1: Code support | R1: Product form detail | S1: Description courte | T1: Description longue | U1: Table des matières | V1: URL image de couverture | W1: cover_file | X1: Nombre de pages (pages totales imprimées) | Y1: Largeur | Z1: Hauteur | AA1: Epaisseur | AB1: Poids | AC1: Sujet BISAC principal | AD1: Sujet CLIL principal | AE1: Sujet THEMA principal | AF1: Code public visé ONIX | AG1: GCOI | AH1: Code interne | AI1: active_site | AJ1: active_onix | AK1: price | AL1: availability | AM1: contributeurs_onix | AN1: auteurs_onix | AO1: direction_onix | AP1: traduction_onix | AQ1: compilation_onix | AR1: openedition_url | AS1: EAN13 (texte) | AT1: Disponibilité (code ONIX) | AU1: Statut publication (code ONIX) | AV1: BIC_BIC code sujet | AW1: BIC_Qualificatif géographique BIC | AX1: BIC_Qualificatif de langue BIC (langue comme sujet) | AY1: BIC_Qualificatif de période historique BIC | AZ1: BIC_Qualificatif de niveau scolaire BIC | BA1: BIC_Qualificatif BIC du niveau de lecture et de l’intérêt particulier | BB1: Apple conseil parental | BC1: Code Evaluation ONIX du public adulte | BD1: THEMA_Classification (raw) | BE1: THEMA_Codes (liste ;) | BF1: THEMA_Principal | BG1: THEMA_Secondaires | BH1: THEMA_Qualif_lieu | BI1: THEMA_Qualif_langue | BJ1: THEMA_Qualif_période | BK1: THEMA_Qualif_niveau_scolaire | BL1: THEMA_Qualif_niveau_lecture | BM1: THEMA_Qualif_style | BN1: THEMA_Code support | BO1: THEMA_Code détail présentation
A2: 9791024019826 | C2: Penser l'éducation, n° 58 | E2: Auteurs diverts | F2: Auteurs divers | J2: Presses universitaires de Rouen et du Havre | L2: Penser l'éducation | M2: 58 | N2: 46317 | O2: 1 | P2: Livre broché | Q2: BC | S2: La revue Penser l'éducation s’inscrit dans le champ spécifique qui croise la philosophie de l’éducation et l’histoire des idées pédagogiques. | T2: La revue Penser l'éducation s’inscrit dans le champ spécifique qui croise la philosophie de l’éducation et l’histoire des idées pédagogiques. Ces deux aspects sont reliés et relèvent de la philosophie de l’éducation. Penser l’éducation n’est pas un titre anodin, il porte une injonction et une promesse : en ces temps de mutation, il s’agit de (re)penser, à nouveaux frais, l’éducation, dans ses principes, ses finalités, ses valeurs, ses pratiques et leurs conséquences. Le numéro 58 explore des sujets tels que le système éducatif guyanais ; les transformations du corps des CPE par le concours ; la régulation des désordres à l'école ; la philosophie de Bernard Stiegler face à la cris de l'éducation ; la communauté de recherche philosophique et orientante et enfin la rencontre des épistémologies du Nord et du Sud. En fin d'opus : une recension, les rubriques « Les fonds du MUNAÉ » et « Penser l’éducation ailleurs ». | U2: <p>François Lechby - Prise en compte des cultures corporelles des sociétés businenge : une intégration dans le système éducatif guyanais ?<br/> Sofia Hachemi - Le concours, un analyseur des transformations du corps des conseillers principaux d’éducation<br/> Gwénaël Lefeuvre, Rémi Bonasio et Bruno Fondeville - Régulation des désordres à l’école : enjeux d’enseignement-apprentissage<br/> Romain Mollard - La philosophie de l’éducation de Bernard Stiegler et la crise de l’éducation à l’ère des technologies numériques : une introduction<br/> Charlie Renard et Elodie Chaumont - La communauté de recherche philosophique et orientante : proposition éducative pour s’orienter au défi de l’inanticipable<br/> Adriana-Renée Tobos et Marie Stoecklin Burr - Rencontre entre les épistémologies du Nord et du Sud : pour une nouvelle écriture de la vie<br/> Recension par Henri Louis Go: Riondet, X. (2025). À l’école althussérienne. Aperçus d’une (non) philosophie de l’éducation. Le Bord de l’Eau, 240 p.<br/> « Les fonds du MUNAÉ », par Kristell Gilbert, documentaliste au Musée national de l’Éducation: Dessins d’enfants (1936-1941) : du Munaé à l’UNESCO<br/> | W2: 9791024019826.jpg | X2: 240 | Y2: 15.5 | Z2: 23 | AA2: 1.5 | AB2: 350
A3: 9791024019796 | C3: Saintuaires | D3: Reliques et reliquaires dans les textes français des XIe-XVIe siècles | E3: Albert, Sophie, B15;Heckmann, Hubert, B15 | F3: Sophie Albert; Hubert Heckman | J3: Presses universitaires de Rouen et du Havre | N3: 46345 | O3: 1 | P3: Livre broché | Q3: BC | S3: Tout en s’appuyant sur les travaux des historien·nes, le volume inscrit l’étude des reliques dans une perspective transdisciplinaire | T3: Tout en s’appuyant sur les travaux des historien·nes, le volume inscrit l’étude des reliques dans une perspective transdisciplinaire : il rassemble les réflexions de chercheurs en histoire, en histoire de l’art et en littérature. Il embrasse un champ chronologique allant du XIe au XVIe siècle, et une pluralité de genres et de registres : textes hagiographiques, mais aussi épiques, romanesques, dramatiques, comiques, lyriques et courtois. Cette ouverture disciplinaire, chronologique et générique, de même que le croisement des méthodes et des points de vue, éclairent la manière dont les corpus français médiévaux pensent, disent et donnent à voir les reliques, réelles ou métaphoriques. | U3: <p>Introduction par Hubert Heckmann<br/> Des fictions apocryphes à l’aventure chevaleresque<br/> Jean-Marie Sansterre, Véronique et son image-relique du Christ dans quelques textes français de la fin du XIIe au début du XIVe siècle<br/> Beate Langenbruch, Reliques et saints de Rhénanie dans la construction d’un récit épique français : le témoignage de Renaut de Montauban<br/> Catherine Nicolas, La sainte chapelle du Graal : imaginaire du morceau et translation des reliques dans le Haut Livre du Graal<br/> De dames, de saintes et de vierges<br/> Françoise Laurent, Traduire la Vie de sainte Léocade : les Miracles de Nostre Dame de Gautier de Coinci et le livre reliquaire<br/> Gérard Gros, Une relique, en somme efficace : le saint soulier de la Vierge Soissons (Gautier de Coinci, Miracles de Nostre Dame, IV, Item dou soller)<br/> Denis Hüe, Marie sacraire, le reliquaire vide<br/> Adriane Boussac, Il n’avoit de remanant de s’amie que le seul gant. Le gant, relique d’amour dans le Cléomadès d’Adenet le roi<br/> Laëtitia Tabard, Les reliques des martyrs d’amour dans quelques dits et poèmes allégoriques du XVe siècle<br/> Reliques en scènes, reliques en jeu<br/> Thierry Revol, La dramaturgie des reliques dans les entrées royales au XVe siècle<br/> Jean-Pierre Bordier, Dévotion et dérision : deux usages des reliques au théâtre<br/> Véronique Dominguez, Rappeler la Passion : l’opsis et la couronne d’épines (XIIIe-XVIe siècles)<br/> Fabienne Pomel, La relique burlesque ou le jeu avec le signe : métonymie, métaphores et substitutions facétieuses<br/> Coda<br/> François Lecercle, La littérature de l’image-relique dans la Contre-Réforme<br/> Conclusion par Sophie Albert : La relique : traversée</p> | W3: 9791024019796.jpg | X3: 350 | Y3: 15.5 | Z3: 23 | AA3: 2 | AB3: 450
A4: 9791024019673 | C4: Les revues au cœur des échanges culturels entre l'Autriche et la France | D4: XIXe-XXIe siècle | E4: Lacheny, Marc, B15;Aurélie, Le Née, B15 | F4: Marc Lacheny; Aurélie Le Née | J4: Presses universitaires de Rouen et du Havre | L4: France-Autriche | N4: 46317 | O4: 1 | P4: Livre broché | Q4: BC | S4: Les revues, par leur périodicité, la diversité de leur contenu et de leurs contributeurs, mais aussi par leurs moyens de diffusion apparaissent comme des opérateurs de premier plan des échanges interculturels. | T4: Les revues, par leur périodicité, la diversité de leur contenu et de leurs contributeurs, mais aussi par leurs moyens de diffusion apparaissent comme des opérateurs de premier plan des échanges interculturels. Le présent ouvrage propose de se pencher sur leur rôle dans les interactions entre l’Autriche et la France du XIXe au XXIe siècle. Il permet d’appréhender l’image de l’autre pays véhiculée par des revues artistiques, sociopolitiques ou académiques. Composé de contributions de spécialistes de l’Autriche et du dialogue interculturel entre l’Autriche et la France, l’ouvrage met en évidence la diversité des revues et des échanges entre les deux pays, et ce faisant, dessine les contours d’une histoire culturelle européenne. | U4: <p>Introduction, Marc Lacheny et Aurélie Le Née<br/> Première partie : Regards socioculturels des revues autrichiennes sur la France au XIXe siècle<br/> Image de la France et (non-)transfert d’idées dans la revue <i>Carinthia</i> (1811-1848/1849), Ute Weinmann<br/> Le vaudeville et la presse autrichienne de la premiere moitié du XIXe siècle, Maria Piok<br/> La France vue par l’<i>Österreichische Lehrerinnen Zeitung</i> (1893-1901) : une relecture engagée de la modernité, Sylvie Arlaud<br/> Deuxième partie : Les revues d’art et de musique de la seconde moitié du XIXe siècle à la première moitié du XXe siècle<br/> La Sécession viennoise dans les revues artistiques françaises (1897-1937), Irène Cagneau<br/> L’Autriche a la découverte de la musique française, Jean-François Candoni<br/> Paris-Vienne ou l’axe des avant-gardes ?, Sophie Picard<br/> Troisième partie : De la France à l’Autriche, de l’Autriche à la France : la revue <i>Austriaca</i>, de 1975 à nos jours<br/> La revue <i>Austriaca</i>, agent des transferts culturels entre la France et l’Autriche, Jacques Lajarrige<br/> Les auteur·e·</p> | W4: 9791024019673.jpg | X4: 198 | Y4: 15.5 | Z4: 23 | AA4: 1.9 | AB4: 300 | AI4: TRUE | AJ4: TRUE | AK4: 13 | AL4: À paraître | AM4: Lacheny, Marc; Aurélie, Le Née, B15 | AS4: 9791024019673 | AT4: 20 | AU4: 2
A5: 9791024019765 | C5: Les Oraisons funèbres de Bossuet | D5: Ou le ravissement de la mort | E5: Lyraud, Pierre | F5: Pierre Lyraud | J5: Presses universitaires de Rouen et du Havre | L5: Cours | N5: 46345 | O5: 1 | P5: Livre broché | Q5: BC | S5: <i>Les oraisons funèbres</i> de Bossuet, oscillant entre déploration et consolation, grandeur et néant, ne correspondent pas à l’image pétrifiante qu’en donne notre histoire littéraire. | T5: <i>Les oraisons funèbres</i> de Bossuet, oscillant entre déploration et consolation, grandeur et néant, ne correspondent pas à l’image pétrifiante qu’en donne notre histoire littéraire. Réinscrivant ces discours dans leur tradition rhétorique et mettant au jour les tensions qui les traversent, cet essai réinscrit ces discours dans leur tradition rhétorique, met au jour leurs tensions, et montre que la mémoire de la perte est convertie en ressource pour l’avenir de la communauté endeuillée. | W5: 9791024019765.jpg | X5: 200 | Y5: 15.5 | Z5: 23 | AA5: 1.8 | AB5: 300 | AF5: 6 | AI5: TRUE | AJ5: TRUE | AK5: 13 | AL5: À paraître | AM5: Lyraud, Pierre | AS5: 9791024019765 | AT5: 20 | AU5: 2
A6: 9791024019734 | C6: Faire du jour la nuit | D6: Lorenzaccio ou les ombres du pouvoir | E6: Mentzel, Sophie | F6: Sophie Mentzel | J6: Presses universitaires de Rouen et du Havre | L6: Cours | N6: 46345 | O6: 1 | P6: Livre broché | Q6: BC | S6: Pièce conçue pour la lecture mais dotée d’une puissance scénique manifeste, "Lorenzaccio" de Musset est une œuvre du paradoxe et du renversement : le vice y masque la vertu, le pouvoir s'y révèle déprédation, et les espaces comme les consciences s’y défont sous le poids de la corruption et de l'inertie. | T6: Pièce conçue pour la lecture mais dotée d’une puissance scénique manifeste, "Lorenzaccio" de Musset est une œuvre du paradoxe et du renversement : le vice y masque la vertu, le pouvoir s'y révèle déprédation, et les espaces comme les consciences s’y défont sous le poids de la corruption et de l'inertie. Cet ouvrage analyse le clair-obscur qui structure la pièce, de la sombre ruelle au palais ducal. Il montre comment l'espace florentin fonctionne à la fois comme révélateur des âmes et tombeau des illusions, et comment, dans cette cité où lieux du pouvoir et lieux de débauche se confondent, le drame consigne l’échec du politique. Écho au pessimisme des premières années de la monarchie de Juillet, il révèle ainsi la modernité désespérée de Musset. | W6: 9791024019734.jpg | X6: 200 | Y6: 15.5 | Z6: 23 | AA6: 1.8 | AB6: 300 | AF6: 6 | AI6: TRUE | AJ6: TRUE | AK6: 13 | AL6: À paraître | AM6: Mentzel, Sophie | AS6: 9791024019734 | AT6: 20 | AU6: 2
A7: 9791024015880 | B7: manuel-d-entrainement-a-l-apnee-9791024015880 | C7: Manuel d'entraînement à l'apnée | E7: Lemaître, Frédéric, B15 | F7: Frédéric Lemaître | J7: Presses universitaires de Rouen et du Havre | N7: 46752 | O7: 1 | P7: Livre broché | Q7: BC | V7: https://www.pun-ed.fr/resources/titles/28777100909220/images/0f6b1f657ac30ab76519ed4c677e9909/HIGHQ/9791024015880.jpg | W7: 9791024015880.jpg | AG7: 28777100909220 | AI7: TRUE | AJ7: TRUE | AK7: 29 | AL7: À paraître | AM7: Lemaître, Frédéric, B15 | AS7: 9791024015880 | AT7: 20 | AU7: 4 | AV7: W;WSSC | BB7: 0 | BD7: SPC | BE7: SPC | BF7: SPC | BN7: BC
A8: 9791024018966 | B8: histoire-de-rouen-vol-2-9791024018966 | C8: Histoire de Rouen, vol. 2 | D8: De 1815 à nos jours | E8: Marec, Yannick, B15 | F8: Yannick Marec | J8: Presses universitaires de Rouen et du Havre | N8: 46289 | O8: 1 | P8: Livre broché | Q8: BC | S8: Ce second volume de l'Histoire de Rouen couvre la période 1815 à nos jours. Ouvrage collectif illustré, rédigé par près d’une quinzaine d’auteurs, il aborde les différents aspects, économiques, sociaux, politiques, patrimoniaux et culturels d’une grande cité, siège de la Métropole Rouen-Normandie. | T8: <p>Durant la période contemporaine, la ville de Rouen a pu apparaître, comme une des toutes premières cités de l'espace hexagonal, en particulier avec son complexe industriel et portuaire. Certains Rouennais ont aussi acquis un rayonnement international comme le grand écrivain Gustave Flaubert, ou encore le prix Nobel de médecine, Charles Nicolle.</p> <p>Rouen se caractérise aussi par la richesse de son patrimoine et la diversité des initiatives culturelles locales. En même temps, le développement urbain doit prendre en compte de nouvelles aspirations, notamment écologiques, les effets délétères d’une industrialisation rapprochée, ayant été, à plusieurs reprises, durement ressentis.</p> | U8: <p>Prologue</p> <p><strong>Chapitre 1.</strong><strong> Rouen entre Monarchie, Empire et République (1815-1870), par Yannick Marec</strong></p> <p>Stéphane Rioland, Jules Adeline et<em> Rouen tel qu'il aurait pu être. Proposition d'un présent possible</em>&nbsp;</p> <p>Karl Feltgen, Le Choléra de 1832</p> <p>Yannick Marec, 1830 et 1848 dans l'imaginaire social et politique rouennais&nbsp;: significations et prolongements</p> <p>Bénédicte Percheron, L'enclos Sainte-Marie&nbsp;: Naissance d’un sanctuaire des sciences</p> <p><strong>Chapitre 2. </strong><strong>Rouen, entre République modérée et République sociale&nbsp;? (1870-1914), par </strong><strong>Yannick Marec</strong></p> <p>Joëlle Robert, Le monument Louis Bouilhet &nbsp;&nbsp;&nbsp;&nbsp;</p> <p>Stéphane Rioland, Jules Adeline habitant et illustrateur des villes&nbsp;</p> <p>Bénédicte Percheron, Un enclos pour une République des Sciences</p> <p>Karl Feltgen, La grippe russe de 1889 &nbsp;</p> <p><strong>Chapitre 3.</strong><strong> Art, Culture et patrimoine au XIX<sup>e</sup> siècle, par </strong><strong>Claire Maingon</strong> &nbsp;</p> <p>Joëlle Robert, Flaubert et Rouen</p> <p>Yvan Leclerc, Louis Bouilhet&nbsp;: Rouen Paris et retour</p> <p><strong>Chapitre 4. </strong><strong>La guerre comme horizon&nbsp;? (1914-1940). Rouen entre renouveau et stagnation, par </strong><strong>Yannick Marec</strong></p> <p>Karl Feltgen, La grippe espagnole de 1918</p> <p>Michel Croguennec, Le renouveau du port de Rouen</p> <p>Réjane Silighini, Le culte rouennais de Jeanne d’Arc et les fêtes du Ve centenaire en 1931</p> <p>Loïc Vadelorge, La vie culturelle à Rouen dans l’entre-deux guerres</p> <p><strong>Chapitre 5.</strong><strong> Souffrances, destructions et reconstruction (1940-1958), par Jean-Marie Cipolat-Gotet</strong>&nbsp;</p> <p>Cécile Anne-Sibout, Pierre René Wolf, patron de presse régionale (1945-1972)</p> <p>J-M Cipolat-Gotet, Les années 1950-1960&nbsp;: redéploiement industriel et perte d’autonomie&nbsp;</p> <p><strong>Chapitre 6. </strong><strong>Expansion et modernisation (1958-1968), par </strong><strong>Jean-Marie Cipolat-Gotet</strong> &nbsp;&nbsp;&nbsp;&nbsp;</p> <p>Michel Croguennec, La renaissance du port&nbsp;: le port et la nouvelle industrialisation jusqu’à Haropa</p> <p><strong>Chapitre 7.</strong> <strong>Rouen et sa périphérie, au temps de Jean Lecanuet (1968-1993), par </strong><strong>Cécile Anne-Sibout</strong></p> <p>La désindustrialisation</p> <p>Loïc Vadelorge, Rouen ville universitaire</p> <p><strong>Chapitre 8. </strong><strong>Rouen à la charnière du XX<sup>e</sup> et du XXI<sup>e</sup> siècle. Essai d’histoire du temps présent, par </strong><strong>Loïc Vadelorge</strong></p> <p>Réjane Silighini, L’Historial Jeanne d’Arc</p> <p>Michel Croguennec et Loïc Vadelorge, Lubrizol ou la quadrature du cercle de l’aménagement métropolitain</p> <p>Michel Croguennec, La raffinerie de pétrole de Petit-Couronne</p> <p>Françoise Lucchini, Les pratiques culturelles de la Métropole Rouen Normandie&nbsp;</p> <p><strong>Chapitre 9. </strong><strong>L’agglomération rouennaise depuis les années 1990, par </strong><strong>Arnaud Brennetot</strong></p> <p>Michel Croguennec, Le port, de la patrimonialisation à la reconversion de l’emprise foncière</p> <p>&nbsp;</p> <p>Epilogue par Yannick Marec</p> <p>Postface par Michel Bussi</p> <p>Bibliographie</p> | V8: https://www.pun-ed.fr/resources/titles/28777100057900/images/2bd388f731f26312bfc0fe30da009595/HIGHQ/9791024018966.jpg | W8: 9791024018966.jpg | X8: 460 | Y8: 18 | Z8: 24 | AB8: 1000 | AC8: HIS013000 | AD8: 3394 | AF8: 6 | AG8: 28777100057900 | AH8: 9791024018966 | AI8: TRUE | AJ8: TRUE | AK8: 35 | AL8: À paraître | AM8: Marec, Yannick, B15 | AS8: 9791024018966 | AT8: 20 | AU8: 2 | AV8: HBJ | BB8: 0 | BN8: BC
A9: 9791024019291 | B9: introduction-a-la-theorie-de-l-information-9791024019291 | C9: Introduction à la théorie de l'information | D9: Travaux pratiques en python | E9: Omar Khadir | F9: Omar Khadir | J9: Presses universitaires de Rouen et du Havre | L9: Cours | N9: 46289 | O9: 1 | P9: Livre broché | Q9: BC | S9: Ce livre est un cours sur la théorie de l'information destiné aux étudiants en licence de mathématiques, d’informatique ou d’électronique et à ceux des grandes écoles. C’est un support pédagogique pour des enseignements adaptés à ces niveaux. Il contient plus de cent trente exercices corrigés et des travaux pratiques traités par le logiciel Python. | T9: <p>La théorie de l'information intervient dans plusieurs disciplines telles que les réseaux de communication, la robotique, l'intelligence artificielle, le e-commerce ou la cybersécurité. Ce livre est un cours sur la théorie de l'information destiné aux étudiants en licence de mathématiques, d’informatique ou d’électronique et à ceux des grandes écoles. C'est un support de cours pour des enseignements correspondant à ces niveaux. Il contient plus de cent trente exercices corrigés et des travaux pratiques testés par le logiciel Python. Les sujets traités concernent le codage et la mesure de l'information, le codage des sources, les canaux discrets sans mémoire et les codes correcteurs d'erreurs.</p> | U9: <p>Préface</p> <p>Remerciements</p> <p><strong>1 Généralités sur le codage de l'information 1</strong></p> <p>1.1 Introduction</p> <p>1.2 Les codes historiques</p> <p>1.3 Source et codage de source</p> <p>1.4 Exercices</p> <p>1.5 Corrigé des exercices</p> <p>1.6 Travaux pratiques</p> <p>1.7 Corrigé des TP</p> <p><strong>2 Mesure de l'information</strong></p> <p>2.1 Introduction</p> <p>2.2 Espace probabilisé discret</p> <p>2.3 Entropie de Shannon d'une source</p> <p>2.4 Une définition de l'information mutuelle</p> <p>2.5 Exercices</p> <p>2.6 Corrigé des exercices</p> <p>2.7 Travaux pratiques</p> <p>2.8 Corrigé des TP</p> <p><strong>3 Codage des sources discrètes</strong></p> <p>3.1 Codes et Test de Sardinas et Patterson</p> <p>3.2 Les codes préfixes</p> <p>3.3 Premier théorème de Shannon</p> <p>3.4 Algorithme de compression LZ77</p> <p>3.5 Exercices</p> <p>3.6 Corrigé des exercices</p> <p>3.7 Travaux pratiques</p> <p>3.8 Corrigé des TP</p> <p><strong>4 Canaux discrets sans mémoire 146</strong></p> <p>4.1 Généralités</p> <p>4.2 Capacité d'un canal</p> <p>4.3 Capacité d'un canal symétrique</p> <p>4.4 Capacité d'un canal binaire à effacement</p> <p>4.5 Le second théorème de Shannon</p> <p>4.6 Exercices</p> <p>4.7 Corrigé des exercices</p> <p>4.8 Travaux pratiques</p> <p>4.9 Corrigé des TP</p> <p><strong>5 Les codes correcteurs d'erreurs</strong></p> <p>5.1 Introduction</p> <p>5.2 Le code de Hamming</p> <p>5.3 Le code de Viterbi</p> <p>5.4 Exercices</p> <p>5.5 Corrigé des exercices</p> <p>5.6 Travaux pratiques</p> <p>5.7 Corrigé des TP</p> <p>Table des figures</p> <p>Bibliographie</p> <p>Index</p> | W9: 9791024019291.jpg | X9: 230 | Y9: 15.5 | Z9: 23 | AB9: 400 | AC9: COM031000 | AD9: 3194 | AF9: 6 | AG9: 28777100421020 | AH9: 9791024019291 | AI9: TRUE | AJ9: TRUE | AK9: 18 | AL9: À paraître | AM9: Khadir, Omar, A01 | AN9: Omar Khadir | AS9: 9791024019291 | AT9: 10 | AU9: 2 | AV9: GPJ | BB9: 0 | BN9: BC
A10: 9791024019420 | B10: eduquer-et-former-depuis-la-pandemie-9791024019420 | C10: Éduquer et former depuis la pandémie | D10: Stabilité et changements | E10: Papi, Cathia, B15; Boéchat-Heer, Stéphanie, B15; Rinaudo, Jean-Luc, B15 | F10: Cathia Papi | J10: Presses universitaires de Rouen et du Havre | L10: Numérique en éducation | M10: 4 | N10: 46289 | O10: 1 | P10: Livre broché | Q10: BC | S10: En 2020, la COVID19 a brutalement eu pour effet la fermeture massive, au niveau mondial, des établissements d'enseignement et de formation, plongeant brutalement enseignants et apprenants dans une forme imposée d’enseignement-apprentissage à distance. Quatre ans après la fin des confinements, que reste-t-il de ces transformations brutales ? | T10: <p>Cet ouvrage résulte de la réflexion de chercheurs réunis lors d'un symposium du Réseau francophone en éducation et formation (REF), à Fribourg en juillet 2024. Mais plus qu’une conclusion, il se veut une ouverture vers des pratiques des acteurs et des institutions qui bénéficient de l’expérience acquise lors des périodes de confinement.</p> <p>À mesure que nous avançons dans un contexte postpandémique, il est en effet crucial de continuer à réfléchir aux pratiques d’enseignement et d’apprentissage, en cherchant à pérenniser les innovations qui ont émergé, en les adaptant aux différents contextes. Les résultats présentés dans cet ouvrage ouvrent des pistes pour une réflexion plus approfondie sur la formation à distance, l’hybridation des pratiques et l’engagement des apprenants, en montrant l'importance d'une approche réfléchie et adaptable face aux défis éducatifs. Ils appellent à une mobilisation collective pour intégrer de manière durable les leçons tirées de la pandémie, afin de bâtir un avenir éducatif inclusif et innovant.</p> | U10: <p><em>Préface</em><br /> Les leçons de la crise</p> <p>À marée basse</p> <p>De quelques changements de l'activité enseignante depuis le passage par la formation à distance</p> <p>De la continuité pédagogique à la transformation des pratiques pédagogiques en enseignement supérieur. Retour sur l'intégration des outils numériques dans les dispositifs innovants pendant et après la pandémie</p> <p>Interroger la pandémie en tant que levier pour le développement de l'hybridation dans les formations</p> <p>L’accompagnement des enseignants face à l’équipement massif des élèves par la collectivité au lendemain de la pandémie. Le cas du Pack Numérique Lycéen dans les lycées professionnels normands</p> <p>Nature de la motivation et Open Badges dans un contexte de postpandémie</p> <p>L’ingénierie pédagogique dans les entités publiques du Québec en période postpandémique</p> <p>Présence du numérique en éducation durant la pandémie&nbsp;: perceptions de parents et d’enseignants canadiens de tous les niveaux scolaires</p> <p>L’évolution du sentiment de compétences numériques et des stratégies d’ajustement des étudiant·e·s avant et après la pandémie</p> <p>Vécu de cours de danse comodaux&nbsp;: l’expérience de professeures et d’apprenantes en contexte de loisir québécois</p> <p>Accords perdus</p> <p>La présence à distance. Une analyse didactique clinique du temps didactique</p> <p><em>Conclusion</em><br /> Quel est l’impact à court et long terme des pratiques innovantes forcées ?</p> <p><em>Postface</em></p> <p><em>Bibliographie</em></p> <p><em>Les auteurs</em></p> | W10: 9791024019420.jpg | Y10: 15.5 | Z10: 23 | AB10: 400 | AC10: EDU000000;EDU026000;EDU029000;EDU059000;ET;TP;ET050;ET034;TP086 | AD10: 3080 | AF10: 5 | AG10: 28777100857700 | AI10: TRUE | AJ10: TRUE | AK10: 15 | AL10: À paraître | AM10: Papi, Cathia, B15; Boéchat-Heer, Stéphanie, B15; Rinaudo, Jean-Luc, B15 | AS10: 9791024019420 | AT10: 10 | AU10: 2 | AV10: Y;YQ | BB10: 0 | BN10: BC
A11: 9791024019543 | B11: le-rire-colonial-9791024019543 | C11: Le rire colonial | D11: La presse satirique illustrée face à la colonisation (1830-1990) | E11: Sofiane Taouchichet | F11: Sofiane Taouchichet | J11: Presses universitaires de Rouen et du Havre | L11: Charivari | M11: 4 | N11: 46289 | O11: 1 | P11: Livre broché | Q11: BC | S11: Histoire des représentations satiriques de la colonisation, entre 1829 et 1990. L'ouvrage est structuré en cinq parties : Histoire de la presse satirique ; La presse satirique illustrée face à l’histoire coloniale ; La stéréotypie coloniale ; Le miroir colonial ; Mécaniques et usages de la presse satirique. | T11: <p>Entre 1829 et 1990, la presse satirique illustrée française accompagne la formation et le chute du second empire colonial. Entre exaltation des conquêtes et dénonciation des violences, elle livre un regard ambivalent où la caricature révèle toutes les ambiguïtés de l'histoire coloniale et offre un miroir mouvant, drôle ou cruel, des sensibilités à l’égard de la colonisation. L’analyse, fondée sur un vaste corpus satirique, met en lumière stéréotypes, usages publics et héritages visuels d’un pan méconnu de la culture impériale. Les images révèlent comment, au fil des pages et des rires, la satire participe à façonner le regard public et à inscrire, jusque dans les imaginaires, les ambiguïtés et les héritages de l’empire.</p> | U11: <p><strong>Préface</strong><br /> <em>Le repas des cannibales</em><br /> <br /> <strong>Introduction</strong></p> <p><strong>Chapitre I.&nbsp;Presse satirique illustrée, histoire et objet médiatique</strong></p> <p>Histoire de la presse satirique illustrée</p> <p>La presse satirique illustrée, un genre (populaire) comme un autre</p> <p><strong>Chapitre II. La presse satirique illustrée face à l</strong><strong><span dir="RTL">'</span></strong><strong>histoire coloniale </strong></p> <p>Le Temps des conquêtes</p> <p>D<span dir="RTL">'</span>une guerre à l<span dir="RTL">’</span>autre</p> <p>Effacement de l<span dir="RTL">’</span>empire</p> <p><strong>Chapitre III. La st</strong><strong>éréotypie satirique coloniale </strong></p> <p>Représenter l<span dir="RTL">’</span>espace des colonies, entre connaissances utiles et romanesque</p> <p>Figures génériques</p> <p>L<span dir="RTL">’</span>Arabe</p> <p>Le Noir</p> <p><strong>Chapitre IV. Le Miroir colonial, l</strong><strong><span dir="RTL">’</span></strong><strong>Autre et le Soi-même </strong></p> <p>Relations internationales : le partage du Monde</p> <p>Miroir politique</p> <p>Mission civilisatrice</p> <p>L<span dir="RTL">’</span>Autre, c<span dir="RTL">’</span>est moi</p> <p><strong>Chapitre V. Mécaniques et usages de la presse satirique </strong></p> <p>Faire rayonner la stéréotypie</p> <p>Caractéristiques de la presse satirique</p> <p>Usages de la presse satirique et pouvoir de la caricature coloniale</p> <p>Histoire de la presse satirique illustrée</p> <p>La presse satirique illustrée, un genre (populaire) comme un autre</p> <p><strong>Chapitre II. La presse satirique illustrée face à l</strong><strong><span dir="RTL">’</span></strong><strong>histoire coloniale </strong></p> <p>Le Temps des conquêtes</p> <p>D<span dir="RTL">’</span>une guerre à l<span dir="RTL">’</span>autre</p> <p>Effacement de l<span dir="RTL">’</span>empire</p> <p><strong>Chapitre III. La st</strong><strong>éréotypie satirique coloniale </strong></p> <p>Représenter l<span dir="RTL">’</span>espace des colonies, entre connaissances utiles et romanesque</p> <p>Figures génériques</p> <p>L<span dir="RTL">’</span>Arabe</p> <p>Le Noir</p> <p><strong>Chapitre IV. Le Miroir colonial, l</strong><strong><span dir="RTL">’</span></strong><strong>Autre et le Soi-même </strong></p> <p>Relations internationales : le partage du Monde</p> <p>Miroir politique</p> <p>Mission civilisatrice</p> <p>L<span dir="RTL">’</span>Autre, c<span dir="RTL">’</span>est moi</p> <p><strong>Chapitre V. Mécaniques et usages de la presse satirique </strong></p> <p>Faire rayonner la stéréotypie</p> <p>Caractéristiques de la presse satirique</p> <p>Usages de la presse satirique et pouvoir de la caricature coloniale</p> <p><strong>Conclusion<br /> Annexes<br /> Chronologie sélective<br /> Bibliographie</strong></p> | W11: 9791024019543.jpg | Y11: 19.5 | Z11: 25.5 | AC11: HIS000000;ART000000;ART037000;HIS010000;HIS054000;ET;TP;ET050;TP024 | AD11: 3377 | AF11: 5 | AG11: 28777100307100 | AI11: TRUE | AJ11: TRUE | AK11: 30 | AL11: À paraître | AM11: Taouchichet, Sofiane, A01 | AN11: Sofiane Taouchichet | AS11: 9791024019543 | AT11: 10 | AU11: 2 | AV11: A;AC | BB11: 0 | BN11: BC
A12: 9791024019604 | B12: une-allure-si-vagabonde-9791024019604 | C12: Une allure si vagabonde | D12: Mélanges en l'honneur de Jean-Claude Arnould | E12: Milhe Poutingon, Gérard, B15; Bonnier, Xavier, B15; Provini, Sandra, B15 | F12: Gérard Milhe Poutingon | J12: Presses universitaires de Rouen et du Havre | N12: 46289 | O12: 1 | P12: Livre broché | Q12: BC | S12: Spécialiste de la littérature du XVIe siècle et professeur émérite à l'université de Rouen Normandie, Jean-Claude Arnould a étudié les narrations brèves, Montaigne et Gournay, les paratextes ou la théorie de la traduction. Autant de thèmes abordés par ses collègues réunis dans ce livre hommage d’une variété fidèle à l’esprit de la Renaissance. | T12: <p>Spécialiste de la littérature française du XVI<sup>e</sup> siècle et professeur émérite à l'université de Rouen Normandie, Jean-Claude Arnould est l’auteur de nombreuses éditions critiques et de travaux sur la narration brève et les histoires tragiques, les œuvres de Montaigne et de Marie de Gournay, les paratextes dans les imprimés anciens ou encore la théorie de la traduction au XVI<sup>e</sup> siècle. Autant de thèmes abordés par ses collègues et amis, européens ou sud-américains, réunis dans ce livre hommage d’une variété fidèle à l’esprit de la Renaissance. Leurs études prolongent la réflexion menée par Jean-Claude Arnould sur la transmission et la traduction des œuvres du XVI<sup>e</sup> siècle, de part et d’autre de l’Atlantique.</p> | U12: <p><strong>Remerciements</strong><br /> <br /> Xavier Bonnier et Sandra Provini<br /> <strong>Avant-propos</strong></p> <p><em>Vie professionnelle et bibliographie de Jean-Claude Arnould</em><br /> &nbsp;</p> <p><strong>I<sup>re </sup>partie -&nbsp;&nbsp;Malheurs, valeurs et humeurs dans la littérature du XVI<sup>e</sup>&nbsp;siècle</strong></p> <p>Gérard Milhe Poutingon<br /> Le « triballement » du « tonneau diogenic » : une critique de la paresse au&nbsp;XVI<sup>e</sup>&nbsp;siècle</p> <p>Pascal Debailly<br /> L'indignation satirique et la restauration de la dignité chez Du Bellay</p> <p>José Alexandrino De Souza Filho<br /> La <em>sprezzatura</em>&nbsp;: concept littéraire, mode vestimentaire et attitude comportementale à la Renaissance&nbsp;</p> <p>Michèle Guéret-Laferté et Rafael Afonso Gonçalves<br /> Les manuscrits du <em>Livro</em> de Duarte Barbosa entre pratique médiévale et renouveau des horizons culturels à la Renaissance</p> <p>Witold Konstanty Pietrzak<br /> L’intertexte dans la <em>Continuation des histoires tragiques</em> de François de Belleforest</p> <p>Ariane Ferry<br /> Le puissant désir d’être auteur : de quelques mises en récit de l’histoire du prince Hamlet (John Updike, Saxo Grammaticus, François de Belleforest et Shakespeare)&nbsp;</p> <p>Marie-Claire Thomine et Romain Weber<br /> <em>Les Heures perdues</em> <em>de R. D. M. Cavalier François</em> (1615) et la tradition facétieuse</p> <p><strong>II<sup>e </sup>partie -&nbsp;Traduire, transmettre, commenter le XVI<sup>e</sup>&nbsp;siècle</strong></p> <p>Sebastian Garcia Barrera<br /> Un long XVI<sup>e</sup>&nbsp;siècle&nbsp;? Réflexions indisciplinées sur l’historiographie de la traduction&nbsp;</p> <p>Martha Lucía Pulido Correa<br /> Étienne Dolet, Jean-Claude Arnould et L’Universidad de Antioquia&nbsp;</p> <p>Myriam Dufour-Maître<br /> <em>La Princesse de Clèves</em> : une &nbsp;« chimère » ?</p> <p>Frank Greiner<br /> Francion ou la pensée libre</p> <p>Tony Gheeraert<br /> <em>Les Histoires ou contes du temps passé</em> de Charles Perrault. De la boutade à la méprise</p> <p>Yvan Leclerc<br /> Notes inédites de Flaubert sur Ronsard et Rabelais, extraites d’Étienne Pasquier, <em>Les Recherches de la France</em></p> <p>Stéphanie Champeau<br /> Une « histoire tragique&nbsp;» : <em>Une page d’histoire</em> de Barbey d’Aurevilly</p> <p>Valerio Cordiner<br /> Montaigne, Lafargue et la rentable fainéantise</p> <p><strong>II<sup>e </sup>partie -&nbsp;Saveurs d’ici, saveurs d’ailleurs&nbsp;: échappées littéraires et humanistes</strong></p> <p>Judith Le Blanc<br /> La fine appellation (d’origine contrôlée)&nbsp;: un(e) Arnould peut en cacher un(e) autre</p> <p>Joann Élart<br /> J’ai un canard sur le feu</p> <p>Hervé Baudry<br /> Des livres et du caviar. Éléments pour l’analyse de microcensure</p> <p>Georges Mathieu<br /> Éléments de physiologie du cul-de-lampe christophien</p> <p>Jean Maurice<br /> <em>Les Chardons du Baragan</em>&nbsp;: l’évasion hors du destin</p> <p>Ariane Eissen<br /> Écritures migrantes au féminin (Laura Alcoba, Agota Kristof, Maryam Madjidi, Shumona Sinha)</p> <p>Françoise Simonet-Tenant<br /> Port-Cros ou les vacances de <em>La NRF</em></p> <p><strong>Table des matières</strong></p> | W12: 9791024019604.jpg | Y12: 15.5 | Z12: 23 | AA12: 4 | AC12: LIT000000;LIT004130;LIT020000 | AD12: 3435 | AF12: 5 | AG12: 28777100348690 | AI12: TRUE | AJ12: TRUE | AK12: 30 | AL12: À paraître | AM12: Milhe Poutingon, Gérard, B15; Bonnier, Xavier, B15; Provini, Sandra, B15 | AS12: 9791024019604 | AT12: 10 | AU12: 2 | AV12: D;DS;DSB;DB | BB12: 0 | BN12: BC
A13: 9791024019468 | B13: la-sylloge-parisina-9791024019468 | C13: La Sylloge Parisina | D13: Édition et traduction | E13: Floridi, Lucia, B10 | F13: Lucia Floridi | J13: Presses universitaires de Rouen et du Havre | L13: Ario | M13: 1 | N13: 46289 | O13: 1 | P13: Livre broché | Q13: BC | S13: Ce travail propose la première édition critique moderne – après la princeps de Cramer (1841) – du recueil d'épigrammes grecques connu sous le nom de Sylloge Parisina, traduits en français et en italien, en double format papier et numérique. | T13: <p>Après l'edition <em>princeps</em> de John Anthony Cramer (1841), est proposée ici pour la première fois l'édition critique du recueil d'épigrammes grecques connu sous le nom de <em>Sylloge Parisina</em>, conservé dans un manuscrit du XII<sup>e</sup>-XIII<sup>e</sup> siècle et dans un apographe partiel datant de la moitié du XIV<sup>e</sup> siècle.</p> <p>L'introduction décrit les témoins, discute de la datation, de la structure et du contenu du recueil, réfléchit sur la transmission anthologique de l'épigramme grec et sur son histoire éditoriale. Les épigrammes sont accompagnées de traductions en italien et en français, afin d'être accessibles même aux non-spécialistes. Le format papier traditionnel est accompagné d'une édition numérique, qui permet d'expérimenter de nouvelles formes de visualisation du texte, rendant plus immédiatement perceptibles les différentes structures qu'il prend dans les différents témoins.</p> | U13: <p>Préambule général</p> <p>Introduction</p> <p>&nbsp;</p> <p><strong>I. Transmission anthologique et histoire éditoriale de l'épigramme grec</strong></p> <p><strong>II. La <em>Sylloge Parisina</em></strong></p> <p>Les témoins</p> <p>Relation entre SS et B</p> <p>Structure, contenu et datation du recueil</p> <p>Le texte de S : réductions, divisions et regroupements d'épigrammes</p> <p>Le texte de S : variantes</p> <p>Accords erronés de S avec P et Pl</p> <p><strong>III. Autres témoins utilisés dans cette édition</strong></p> <p>Les compilations majeures : P et Pl (et l'apographe Q)</p> <p>Recueils mineurs porteurs d'une tradition indépendante</p> <p>Recueils mineurs dérivés de Planudes</p> <p>&nbsp;</p> <p>Introduction au texte</p> <p><em>Conspectus Siglorum</em></p> <p>Texte critique</p> <p>Traduction italienne</p> <p>Traduction française</p> <p><em>Auctarium Lectionum</em></p> <p>Annexe</p> <p>Bibliographie</p> <p>Lexique</p> <p>Index des notions</p> | V13: https://www.pun-ed.fr/resources/titles/28777100504790/images/579600f6b6044f107758cdda0ca0aacb/HIGHQ/9791024019468.jpg | W13: 9791024019468.jpg | X13: 200 | Y13: 15.5 | Z13: 23 | AA13: 1.5 | AB13: 400 | AC13: LIT004190 | AD13: 3437 | AF13: 6 | AG13: 28777100504790 | AH13: 9791024019468 | AI13: TRUE | AJ13: TRUE | AK13: 18 | AL13: À paraître | AM13: Floridi, Lucia, B10 | AS13: 9791024019468 | AT13: 10 | AU13: 2 | AV13: DB | BB13: 0 | BN13: BC
A14: 9791024019574 | B14: austriaca-n-98-9791024019574 | C14: Austriaca, n° 98 | E14: Weinmann, Ute, B15; Baric, Daniel, B15 | F14: Ute Weinmann | J14: Presses universitaires de Rouen et du Havre | L14: Austriaca | M14: 98 | N14: 46226 | O14: 1 | P14: Livre broché | Q14: BC | S14: La tenue des Jeux olympiques à Paris en 2024 est apparue comme l'occasion de consacrer pour la première fois un cahier thématique d’"Austriaca" au sport autrichien en général et à l’olympisme en particulier. En explorant l’histoire du sport par le biais de l’olympisme, ce dossier souhaite contribuer à une historiographie multidisciplinaire. | T14: <p>La tenue des Jeux olympiques à Paris en 2024 est apparue comme l'occasion de consacrer pour la première fois un cahier thématique d’<em>Austriaca </em>au sport autrichien en général et à l’olympisme en particulier.</p> <p>En explorant l’histoire du sport par le biais de l’olympisme, ce dossier intitulé "Olympiades" souhaite contribuer à une historiographie résolument multidisciplinaire. Les études réunies s’inscrivent dans une recherche collective sur l’histoire du Mouvement olympique autrichien au sens large, sur une chronologie plus que centenaire, tant dans l’espace habsbourgeois que dans les configurations successives de l’Autriche. Sont rassemblés des articles qui abordent la question de l'olympisme <em>stricto sensu</em> tout en explorant ce qui fait l'originalité de l’essor et du rôle des compétitions olympiques en Autriche.</p> <p>L’un de ces aspects originaux concerne la précocité et la permanence d’un intérêt esthétique et scientifique pour les Jeux de l’Antiquité. En 1733, à l’occasion de l’anniversaire de l’impératrice Élisabeth-Christine de Brunswick-Wolfenbüttel, épouse de l’empereur Charles VI et mère de Marie-Thérèse, Métastase (1698-1782), poète à la cour de Vienne, compose une <em>Olimpiade</em>, un livret en trois actes mêlant intrigues amoureuses sur fond de Jeux olympiques. Le succès de cette thématique olympique mise en scène avec différentes partitions ne se dément pas, notamment avec celle du compositeur tchèque Josef Mysliveček (1737-1781), jouée en 1778, encore reprise à Vienne en 2014 au <em>Theater an der Wien</em>. Les Jeux olympiques sont un spectacle, suscitent un imaginaire, inventés et goûtés à Vienne avant même leur réinvention moderne.</p> <p></p> </P> | U14: <p>Avant-propos</p> <p>Le corps, le sport et ses métaphores<br /> <strong>Daniel BARIC et Ute WEINMANN</strong></p> <p>Julius Jüthner&nbsp;: profil d'un projet pionnier d'histoire du sport antique, de sa genèse à sa postérité, de l'Empire à la République<br /> <strong>Daniel BARIC</strong></p> <p> Otto Herschmann, un pionnier des sports olympiques en Autriche&nbsp;<br /> strong>Matthias MARSCHIK, Rudolf MÜLLNER</strong></p> <p> Die lange Reise des Fußballdoktors Emanuel „Michl" Schwarz<br /> <strong>Wolfgang MADERTHANER</strong></p> <p> Sport und Politik. Die Wiener Sportlandschaft der Zwischenkriegszeit&nbsp;<br /> <strong>Bernhard HACHLEITNER</strong><br /> <br /> Les Olympiades ouvrières de Vienne (1931)&nbsp;: Une démonstration de force en trompe-l'oeil<br /> <strong>Guillaume ROBIN</strong></p> <p>"Ich gehörte noch nicht der allerneuesten Generation an, die durch Fußball, Skilauf und Boxen geschlechtsreif wird" –Joseph Roths skeptisches Verhältnis zu sportlichen Aktivitäten&nbsp;<br /> <strong>Herta Luise OTT</strong></p> <p>« Man hört nur das Beste vom Gedeihen der Berliner Olympiade ». Friedrich Torberg, contempteur des Jeux olympiques de Berlin<br /> <strong>Jacques LAJARRIGE</strong></p> <p>L’Autriche et les Jeux de Hitler à Garmisch-Partenkirchen et Berlin<br /> <strong>Alfred PFOSER</strong></p> <p><strong>Ski alpin et invention de la nation autrichienne&nbsp;: contribution d’une discipline olympique à l’identité nationale dans l’Autriche d’après-guerre<br /> <strong>Ute WEINMANN</strong></p> <p>Karl Schranz, un olympien trop professionnel&nbsp;? Une affaire entre dilemmes olympiques et rivalité franco-autrichienne<br /> ;<strong>Karl ZIEGER</strong></p> <p>Sport und Nationalgefühl;<br /> <strong>Gerald STIEG</strong></p> <p>Résumés/Zusammenfassungen/Abstracts</p> | W14: 9791024019574.jpg | Y14: 15.5 | Z14: 23 | AA14: 1.45 | AB14: 420 | AC14: SPO000000;HIS000000;HIS010000;SPO058000;SPO066000;ET;EV;ET060 | AD14: 3435 | AF14: 5 | AG14: 28777100239170 | AI14: TRUE | AJ14: TRUE | AK14: 25 | AL14: À paraître | AM14: Baric, Daniel, B15; Weinmann, Ute, B15 | AS14: 9791024019574 | AT14: 10 | AU14: 2 | AV14: D;DS;J;W;WZ | BB14: 0 | BN14: BC
A15: 9791024019208 | B15: european-studies-in-sports-history-vol-18-9791024019208 | C15: European Studies in Sports History, vol. 18 | D15: Sport and Religion | E15: Auteurs divers | F15: Auteurs divers | J15: Presses universitaires de Rouen et du Havre | L15: European Studies in Sports History | M15: 18 | N15: 46163 | O15: 1 | P15: Livre broché | Q15: BC | S15: The 18th issue of ESSH joins a long-standing and dynamic academic conversation on the intersection of sport and religion, offering a historical perspective that spans from the 19th century to the present day. Across this period, profound shifts in cultural and social practices have redefined how societies experience ritual, faith and the body. | T15: <p>The eighteenth issue of <em>European Studies in Sport History</em> joins a long-standing and dynamic academic conversation on the intersection of sport and religion, offering a historical perspective that spans from the nineteenth century to the present day. Across this period, profound shifts in cultural and social practices have redefined how societies experience ritual, faith, and the body. Sport has become one of the key spaces in which these transformations are expressed, contested, and sometimes ritualized in new ways. The famous story of Eric Liddell in <em>Chariots of Fire</em>, who refused to run on a Sunday because of his religious convictions, evokes a time when sacred obligations could outweigh Olympic ambition. Today, however, churches often stand empty while stadiums overflow. Collective identity and belonging, once nurtured through religious communities, are increasingly found in sport — through shared chants, symbols, and emotional rituals. The sacred has not disappeared but has migrated, changed form, or found new expressions. The contributions assembled in this volume examine the complex and evolving relationships between religion and sport: from competition to leisure, from amateur practice to professional performance, from sacred rituals to modern spectacles. Authors explore how both spheres have historically shared — and sometimes struggled over — values, spaces, gestures, and communities. The volume also reveals the persistence of religious expressions in contemporary sport, amplified by media and global audiences. Bringing together historians, sociologists, scholars of religion, anthropologists, and philosophers, this special issue offers a multifaceted portrait of how sport has mirrored, replaced, or intertwined with spiritual experience in modern and contemporary societies. It invites readers to reflect on the ways belief, identity, and the body continue to be negotiated on playing fields as much as in places of worship.</p> | U15: <p>Arnd Krüger, Angela Teja </br> <em>Sport and Religion: An Introduction </em></br> Manon Hedenborg White, Daniel Svensson </br> <em>Back to Nature? Natural Training and the Pursuit of Spiritual Well-Being in Swedish Sports Biographies </em></br> Dries Vanysacker </br> <em>John XXIII (1958-1963) and his Attitude towards Sport: just a Go-Between Pope or an Innovator?<em> </br> Florian G. Mildenberger </br> <em>Sport in the German Catholic Community: The Emergence and Relevance of the</em> Deutsche Jugendkraft (DJK) <em>until 1945 </em> Pere Fullana Puigserver, Rafel Morro Aguilar </br> <em>Club Deportivo Sant Felipe (1945-1969). El fonda de documentaci6n deportiva en el archiva del oratorio de Sant Felipe Neri De Palma</em> </br> Silvio Dorigo, Marco Dorigo </br> <em>La ginnastica e i primi sport tra i cattolici sloveni fmo alla prima guerra mondiale (1896-1914)</em> </br> Fatia Terfous </br> <em>Politique et mouvement sportif catholique pendant la seconde guerre mondiale : la question des femmes (1940-1944)</em> </br> Maria Eugenia Garda-Sottile, Isabella Scursatone </br> <em>Why Do We Give an Opinion Instead of Asking? In Search of the Voices and Staries of Muslim Sportswomen and the Wearing of the Hijab</em> </br> Book review </br> Abstracts </p> | W15: 9791024019208.jpg | X15: 200 | Y15: 15.5 | Z15: 23 | AA15: 1.1 | AB15: 342 | AC15: SPO000000 | AD15: 3864 | AF15: 6 | AG15: 28777100345730 | AH15: 9791024019208 | AI15: TRUE | AJ15: TRUE | AK15: 25 | AL15: Disponible | AM15: Auteurs divers, A01 | AN15: Auteurs divers | AS15: 9791024019208 | AT15: 20 | AU15: 4 | AV15: WS;HB | BN15: BC
A16: 9791024019505 | B16: penser-l-education-n-57-9791024019505 | C16: Penser l'éducation, n° 57 | E16: Auteurs divers | F16: Auteurs divers | J16: Presses universitaires de Rouen et du Havre | L16: Penser l'éducation | M16: 57 | N16: 46163 | O16: 1 | P16: Livre broché | Q16: BC | S16: La revue, varia, s'inscrit dans le champ spécifique qui croise la philosophie de l'éducation et l'histoire des idées pédagogiques et en ces temps de mutation, (re)pense, à nouveaux frais, l'éducation, dans ses principes, ses finalités, ses valeurs, ses pratiques et leurs conséquences. | T16: <p>La revue<em> Penser l'éducation</em> est une revue scientifique internationale à comité de lecture, adossée au Centre interdisciplinaire de recherches normand en éducation et en formation (CIRNEF), laboratoire de l'université de Rouen.<br /> Cette revue, qui existe depuis 1996, s'inscrit dans le champ spécifique qui croise la philosophie de l'éducation et l'histoire des idées pédagogiques.<br /> Traditionnellement, ces deux aspects sont reliés et relèvent de la philosophie de l'éducation. <em>Penser l'éducation</em> n'est pas un titre anodin, il porte une injonction et une promesse: en ces temps de mutation, il s'agit de (re)penser, à nouveaux frais, l'éducation, dans ses principes, ses finalités, ses valeurs, ses pratiques et leurs conséquences.<br /> Deux numéros sont publiés chaque année. Ils ont la particularité d'être composés, sans contrainte thématique, uniquement de varia et de comptes rendus de lecture. Depuis 2014, la revue <em>Penser l'éducation</em> est publiée par les Presses universitaires de Rouen et du Havre et en décembre 2022, elle ouvre sa page sur le portail OpenEdition Journals. La revue offre, à partir de 2024, une nouvelle formule en publiant des numéros thématiques ponctuels qui permettent une articulation de contributions autour d'un thème central qui a un écho en philosophie de l'éducation et/ou en histoire des idées pédagogiques. Une jeune rubrique «&nbsp;Penser l'éducation ailleurs&nbsp;» vient complémenter celles déjà existantes&nbsp;: «&nbsp;Recensions&nbsp;» et «&nbsp;Les fonds du MUNAÉ&nbsp;».</p> | U16: <p>Pierre Billouet<br /> <em>De la zététique</em></p> <p>Dominique Broussal<br /> <em>Qui veut la peau de la gamification&nbsp;? Du débat pédagogique comme opportunité de «&nbsp;mise en crise&nbsp;» des modèles de formation</em></p> <p>Elisa Frassetto<br /> <em>Exercices de pensée conceptuelle, imaginative et sociale en classes de troisième et de seconde</em> Renaud Hétier<br /> <em>La démocratie à l'épreuve de l'Anthropocène&nbsp;: quelle réponse éducative&nbsp;?</em></p> <p>Élisabeth Maizonnier-Payelle<br /> <em>Instauration et circulation de la pédagogie d’initiation de Germaine Tortel. Entre voix pédagogiques et voies institutionnelles pour une Education Through Art</em></p> <p>Olivier Marty<br /> <em>Qu’est-ce que le métier d’enseignante du supérieur&nbsp;? Enseigner, (re)chercher et administrer dans le troisième degré</em></p> <p>Sandra Psomas<br /> <em>Des pensées de Hegel sur l’enseignement dans ses Textes pédagogiques : des caractéristiques dialectiques&nbsp;?</em></p> <p><strong>Recension</strong></p> <p>Alain Trouvé, <em>L’enquête et le sens. Littérature et questionnement</em>. (Michel Fabre, L’Harmattan, 2023)</p> <p><strong>Les fonds du MUNAÉ</strong></p> <p><em>La figure de Louis Pasteur dans les collections du Musée national de l’Éducation</em>, par Emily Busato</p> <p><strong>Penser l’éducation ailleurs</strong></p> <p><em>Retour sur l’éducation zapatiste au Mexique, entretien avec Bruno Baronnet</em></p> <p><strong>Résumés</strong></p> <p><strong>Les auteurs</strong></p> | V16: https://www.pun-ed.fr/resources/titles/28777100383440/images/8c2d7d2728733cad5681b6b79ae799e4/HIGHQ/9791024019505.jpg | W16: 9791024019505.jpg | X16: 206 | Y16: 15.5 | Z16: 23 | AA16: 1.1 | AB16: 352 | AC16: PSY012000;PHI000000;PSY000000;PSY030000;ET | AD16: 3013 | AF16: 6 | AG16: 28777100383440 | AH16: 9791024019505 | AI16: TRUE | AJ16: TRUE | AK16: 26 | AL16: Disponible | AM16: Auteurs divers, A01 | AN16: Auteurs divers | AS16: 9791024019505 | AT16: 20 | AU16: 4 | AV16: Y | BB16: 0 | BN16: BC
A17: 9791024018737 | B17: microfinance-et-innovations-9791024018737 | C17: Microfinance et innovations | D17: Un regain de dynamisme de la finance inclusive | E17: Acclassato Houensou, Denis, B15; Galiègue, Xavier, B15; Sossou, Gilles Armand, B15 | F17: Denis Acclassato Houensou | J17: Presses universitaires de Rouen et du Havre | L17: Microfinance contemporaine | M17: 4 | N17: 46072 | O17: 1 | P17: Livre broché | Q17: BC | S17: Face aux défis que la microfinance doit relever, cet ouvrage se structure en trois axes. Il fait un état des lieux de la situation de la microfinance en Afrique subsaharienne, avant de se pencher sur la performance des institutions de microfinance. Enfin, il s'interroge sur les nouvelles tendances observées dans le domaine de la microfinance. | T17: <p>Cet ouvrage est le quatrième de la collection «&nbsp;Microfinance contemporaine&nbsp;» ouverte par l'Association internationale de chercheurs francophones en microfinance (AICFM) crée en 2012 avec le soutien de l’Agence universitaire de la francophonie (AUF). Cette association a pour but de faciliter les échanges – en français – entre chercheurs du Nord et du Sud sur la microfinance et les problèmes qu’elle soulève désormais.</p> <p>Le premier volume, <em>La microfinance contemporaine&nbsp;: défis et perspectives</em>, était issu de journées scientifiques organisées à Brazzaville. Le deuxième, <em>La microfinance contemporaine&nbsp;: crises et mutations</em>, des journées de Douala. Le troisième, <em>La microfinance contemporaine&nbsp;: Le financement de la microfinance</em>, des rencontres de Casablanca. Ce cinquième volume revient sur les journées qui se sont déroulées à l’université d’Abomey-Calavi (Bénin).</p> <p>Face aux défis que la microfinance doit relever, les contributions qui ont été retenues se structurent selon trois grands axes. Tout d’abord, un certain nombre d’entre elles font un <em>état des lieux</em> de la situation de la microfinance en Afrique subsaharienne, en précisant le contexte contemporain dans lequel elle s’inscrit, à savoir une sous-bancarisation et une évolution vers le microcrédit entrepreneurial, dans un contexte de numérisation des moyens de paiement. Ensuite, la <em>performance</em> des institutions de microfinance fait l’objet d’un examen particulier. Cette performance s’explique en comparaisons internationales par des facteurs institutionnels et réglementaires spécifiques à chaque pays, et entre institutions de microfinance sur leur capacité à mobiliser des fonds propres plutôt que des ressources externes. Enfin, un ensemble de contributions s’interrogent sur <em>les nouvelles tendances</em> observées dans le domaine de la microfinance, qui viennent alimenter des débats déjà anciens&nbsp;: le caractère innovant de la microfinance, en termes de public visé et de méthodes de recouvrement, le développement du paiement mobile en chine ou encore la surchauffe observée sur le marché de la microfinance et la complémentarité entre banques traditionnelles et IMF.</p> | U17: <p><strong>Remerciements</strong></p> <p><strong>Avant-propos par Xavier Galiègue</strong></p> <p><strong>Partie 1 - </strong><strong>La microfinance en Afrique subsaharienne : état des lieux</strong></p> <p><em>Les établissements de microfinance et la sous-bancarisation dans la CEMAC</em>, par Hilarion Kontchop</p> <p><em>Microfinance et innovations sociales au Bénin : vers un microcrédit entrepreneurial</em>, par Denis Acclassato Houensou, Achille Barnabé Assouto, Modeste Senou et Sylvain Hekponhoue</p> <p><em>Finance numérique et règlementation de la microfinance dans les pays de l'UEMOA&nbsp;: un survol de la littérature</em>, par Alastaire Alinsato et Eudoxie Bessan</p> <p><em>Droit, finance digitale et croissance économique en Afrique subsaharienne</em>, par Fidèle K. Delidji et Magloire Lanha</p> <p><em>Microfinance, capital social et inégalités</em>, par Maxime Menuet et Patrick Villieu</p> <p>&nbsp;</p> <p><strong>Partie 2 - Quelles performances des institutions de microfinance&nbsp;?</strong></p> <p><em>Facteurs macro-économiques et macro-institutionnels et performances des institutions de microfinance (IMF) dans l'Union Economique et Monétaire Ouest-Africaine (UEMOA)</em>, par Tchapo Gbandi, Mawuli K. Couchoro et Jacques M. Agossou</p> <p><em>Sources de financement et performances des structures financières décentralisées au Bénin</em>, par Yves Hounguevou, Magloire Lanha et Jude Eggoh</p> <p><em>Inclusions financière et foncière&nbsp;: quels effets sur le bien-être des ménages au Bénin&nbsp;?</em>, par Alastaire Sèna Alinsato et Ken'tché Gérard Houndote</p> <p><em>Régime d'incitation et performance des institutions de microfinance au Bénin</em>, par Denis Acclassato Houensou et Melain Modeste Senou</p> <p><em>Exclusion sur les marchés de crédit en présence des coûts de transaction des garanties</em>, par Albert Honlonkou</p> <p>&nbsp;</p> <p><strong>Partie 3 - Nouveaux enjeux, anciens débats&nbsp;?</strong></p> <p><em>Innovations en microfinance ou recours à de vieilles recettes&nbsp;?</em>, par Christian Rietsch</p> <p><em>En Chine, le paiement mobile est-il "&nbsp;monnaie courante&nbsp;"&nbsp;?</em>, par Thierry Pairault</p> <p><em>Freiner un marché de microcrédit en surchauffe : les plafonds de taux d’intérêt sont-ils pertinents&nbsp;?</em>, par Tristan Caballero-Montes, Cécile Godfroid et Marc Labie</p> <p><em>Les liens sociaux et la confiance&nbsp;: quelle influence sur les modes de financement alternatifs des Très Petites Entreprises (TPE)&nbsp;? Une application au Bénin</em>, par Marc Dieudonné Gnanho, Marie-Thérèse Um-Ngouem et Noé Ndjeck</p> <p><em>Complémentarité financière Banque islamique du Sénégal/institutions de microfinance et financement des PME sénégalaises&nbsp;: modélisation et estimation sur données de panel dynamique</em>, par Massamba Souleymane Seck et Ibrahima Thiam</p> | V17: https://www.pun-ed.fr/resources/titles/28777100665710/images/a2cdd86a458242d42a17c2bf4feff069/HIGHQ/9791024018737.jpg | W17: 9791024018737.jpg | X17: 272 | Y17: 15.5 | Z17: 23 | AA17: 2.6 | AB17: 750 | AC17: BUS027000;BUS092000;BUS090000;BUS069000;LAW014000 | AD17: 3177 | AF17: 6 | AG17: 28777100665710 | AI17: TRUE | AJ17: TRUE | AK17: 24 | AL17: Disponible | AM17: Acclassato Houensou, Denis, B15; Galiègue, Xavier, B15; Sossou, Gilles Armand, B15 | AS17: 9791024018737 | AT17: 10 | AU17: 4 | AV17: K;KC;KF;KJ;LB | BB17: 0 | BC17: 1 | BN17: BC
